Traceback (most recent call last):
  File "C:\Users\Martin\anaconda3\envs\py37\lib\site-packages\jupyter_cache\executors\utils.py", line 56, in single_nb_execution
    record_timing=False,
  File "C:\Users\Martin\anaconda3\envs\py37\lib\site-packages\nbclient\client.py", line 1112, in execute
    return NotebookClient(nb=nb, resources=resources, km=km, **kwargs).execute()
  File "C:\Users\Martin\anaconda3\envs\py37\lib\site-packages\nbclient\util.py", line 74, in wrapped
    return just_run(coro(*args, **kwargs))
  File "C:\Users\Martin\anaconda3\envs\py37\lib\site-packages\nbclient\util.py", line 53, in just_run
    return loop.run_until_complete(coro)
  File "C:\Users\Martin\anaconda3\envs\py37\lib\asyncio\base_events.py", line 587, in run_until_complete
    return future.result()
  File "C:\Users\Martin\anaconda3\envs\py37\lib\site-packages\nbclient\client.py", line 554, in async_execute
    cell, index, execution_count=self.code_cells_executed + 1
  File "C:\Users\Martin\anaconda3\envs\py37\lib\site-packages\nbclient\client.py", line 857, in async_execute_cell
    self._check_raise_for_error(cell, exec_reply)
  File "C:\Users\Martin\anaconda3\envs\py37\lib\site-packages\nbclient\client.py", line 760, in _check_raise_for_error
    raise CellExecutionError.from_cell_and_msg(cell, exec_reply_content)
nbclient.exceptions.CellExecutionError: An error occurred while executing the following cell:
------------------
# Vorstellung: MNIST-Daten!
# http://yann.lecun.com/exdb/mnist/
# FashionMNIST: https://github.com/zalandoresearch/fashion-mnist

import gzip
import numpy as np
import numpy as np
from numpy import load
from tensorflow.keras.utils import to_categorical


X_train = load('../02_NN/Dataset/X_train.npy').astype(np.float32)#.reshape(-1, 784)
y_train = load('../02_NN/Dataset/y_train.npy')


#oh = OneHotEncoder()
#y_train_oh = oh.fit_transform(y_train.reshape(-1, 1)).toarray()

X_test=load('../02_NN/Dataset/X_test.npy').astype(np.float32)#.reshape(-1, 784)
y_test=load('../02_NN/Dataset/y_test.npy')

y_train = to_categorical(y_train)
y_test = to_categorical(y_test)
------------------

[1;31m---------------------------------------------------------------------------[0m
[1;31mModuleNotFoundError[0m                       Traceback (most recent call last)
[1;32m~\AppData\Local\Temp/ipykernel_13876/3542694572.py[0m in [0;36m<module>[1;34m[0m
[0;32m      7[0m [1;32mimport[0m [0mnumpy[0m [1;32mas[0m [0mnp[0m[1;33m[0m[1;33m[0m[0m
[0;32m      8[0m [1;32mfrom[0m [0mnumpy[0m [1;32mimport[0m [0mload[0m[1;33m[0m[1;33m[0m[0m
[1;32m----> 9[1;33m [1;32mfrom[0m [0mtensorflow[0m[1;33m.[0m[0mkeras[0m[1;33m.[0m[0mutils[0m [1;32mimport[0m [0mto_categorical[0m[1;33m[0m[1;33m[0m[0m
[0m[0;32m     10[0m [1;33m[0m[0m
[0;32m     11[0m [1;33m[0m[0m

[1;31mModuleNotFoundError[0m: No module named 'tensorflow'
ModuleNotFoundError: No module named 'tensorflow'

