Traceback (most recent call last):
  File "C:\Users\Martin\anaconda3\envs\py37\lib\site-packages\jupyter_cache\executors\utils.py", line 56, in single_nb_execution
    record_timing=False,
  File "C:\Users\Martin\anaconda3\envs\py37\lib\site-packages\nbclient\client.py", line 1112, in execute
    return NotebookClient(nb=nb, resources=resources, km=km, **kwargs).execute()
  File "C:\Users\Martin\anaconda3\envs\py37\lib\site-packages\nbclient\util.py", line 74, in wrapped
    return just_run(coro(*args, **kwargs))
  File "C:\Users\Martin\anaconda3\envs\py37\lib\site-packages\nbclient\util.py", line 53, in just_run
    return loop.run_until_complete(coro)
  File "C:\Users\Martin\anaconda3\envs\py37\lib\asyncio\base_events.py", line 587, in run_until_complete
    return future.result()
  File "C:\Users\Martin\anaconda3\envs\py37\lib\site-packages\nbclient\client.py", line 554, in async_execute
    cell, index, execution_count=self.code_cells_executed + 1
  File "C:\Users\Martin\anaconda3\envs\py37\lib\site-packages\nbclient\client.py", line 857, in async_execute_cell
    self._check_raise_for_error(cell, exec_reply)
  File "C:\Users\Martin\anaconda3\envs\py37\lib\site-packages\nbclient\client.py", line 760, in _check_raise_for_error
    raise CellExecutionError.from_cell_and_msg(cell, exec_reply_content)
nbclient.exceptions.CellExecutionError: An error occurred while executing the following cell:
------------------
# CNN (Max-Pooling, RELU)!

from tensorflow.keras.models import Sequential
from tensorflow.keras.layers import Dense, Conv2D, MaxPooling2D, Flatten

model = Sequential()

model.add(Conv2D(5, kernel_size=(3, 3), activation="relu", input_shape=(28, 28, 1)))
model.add(MaxPooling2D(pool_size=(2, 2)))
model.add(Flatten())
model.add(Dense(5, activation="softmax"))

model.compile(optimizer="rmsprop", loss="categorical_crossentropy", metrics=["accuracy"])

model.fit(
    X_train.reshape(10500, 28, 28, 1),
    y_train,
    epochs=55,
    batch_size=100)
------------------

[1;31m---------------------------------------------------------------------------[0m
[1;31mValueError[0m                                Traceback (most recent call last)
[1;32m~\AppData\Local\Temp/ipykernel_13876/442141933.py[0m in [0;36m<module>[1;34m[0m
[0;32m     14[0m [1;33m[0m[0m
[0;32m     15[0m model.fit(
[1;32m---> 16[1;33m     [0mX_train[0m[1;33m.[0m[0mreshape[0m[1;33m([0m[1;36m10500[0m[1;33m,[0m [1;36m28[0m[1;33m,[0m [1;36m28[0m[1;33m,[0m [1;36m1[0m[1;33m)[0m[1;33m,[0m[1;33m[0m[1;33m[0m[0m
[0m[0;32m     17[0m     [0my_train[0m[1;33m,[0m[1;33m[0m[1;33m[0m[0m
[0;32m     18[0m     [0mepochs[0m[1;33m=[0m[1;36m55[0m[1;33m,[0m[1;33m[0m[1;33m[0m[0m

[1;31mValueError[0m: cannot reshape array of size 379330560 into shape (10500,28,28,1)
ValueError: cannot reshape array of size 379330560 into shape (10500,28,28,1)

