Traceback (most recent call last):
  File "C:\Users\Martin\anaconda3\envs\py37\lib\site-packages\jupyter_cache\executors\utils.py", line 56, in single_nb_execution
    record_timing=False,
  File "C:\Users\Martin\anaconda3\envs\py37\lib\site-packages\nbclient\client.py", line 1112, in execute
    return NotebookClient(nb=nb, resources=resources, km=km, **kwargs).execute()
  File "C:\Users\Martin\anaconda3\envs\py37\lib\site-packages\nbclient\util.py", line 74, in wrapped
    return just_run(coro(*args, **kwargs))
  File "C:\Users\Martin\anaconda3\envs\py37\lib\site-packages\nbclient\util.py", line 53, in just_run
    return loop.run_until_complete(coro)
  File "C:\Users\Martin\anaconda3\envs\py37\lib\asyncio\base_events.py", line 587, in run_until_complete
    return future.result()
  File "C:\Users\Martin\anaconda3\envs\py37\lib\site-packages\nbclient\client.py", line 554, in async_execute
    cell, index, execution_count=self.code_cells_executed + 1
  File "C:\Users\Martin\anaconda3\envs\py37\lib\site-packages\nbclient\client.py", line 857, in async_execute_cell
    self._check_raise_for_error(cell, exec_reply)
  File "C:\Users\Martin\anaconda3\envs\py37\lib\site-packages\nbclient\client.py", line 760, in _check_raise_for_error
    raise CellExecutionError.from_cell_and_msg(cell, exec_reply_content)
nbclient.exceptions.CellExecutionError: An error occurred while executing the following cell:
------------------
# load numpy array from npy file

# load array

X_train=load('../01_Dataset/dataset_28x28/X_train.npy').astype(np.float32) * 1.0/255.0 # normalisieren
y_train=load('../01_Dataset/dataset_28x28/y_train.npy')
X_test=load('../01_Dataset/dataset_28x28/X_test.npy').astype(np.float32) * 1.0/255.0  # normalisieren
y_test=load('../01_Dataset/dataset_28x28/y_test.npy')
------------------

[1;31m---------------------------------------------------------------------------[0m
[1;31mNameError[0m                                 Traceback (most recent call last)
[1;32m~\AppData\Local\Temp/ipykernel_3928/361840572.py[0m in [0;36m<module>[1;34m[0m
[0;32m      3[0m [1;31m# load array[0m[1;33m[0m[1;33m[0m[1;33m[0m[0m
[0;32m      4[0m [1;33m[0m[0m
[1;32m----> 5[1;33m [0mX_train[0m[1;33m=[0m[0mload[0m[1;33m([0m[1;34m'../01_Dataset/dataset_28x28/X_train.npy'[0m[1;33m)[0m[1;33m.[0m[0mastype[0m[1;33m([0m[0mnp[0m[1;33m.[0m[0mfloat32[0m[1;33m)[0m [1;33m*[0m [1;36m1.0[0m[1;33m/[0m[1;36m255.0[0m [1;31m# normalisieren[0m[1;33m[0m[1;33m[0m[0m
[0m[0;32m      6[0m [0my_train[0m[1;33m=[0m[0mload[0m[1;33m([0m[1;34m'../01_Dataset/dataset_28x28/y_train.npy'[0m[1;33m)[0m[1;33m[0m[1;33m[0m[0m
[0;32m      7[0m [0mX_test[0m[1;33m=[0m[0mload[0m[1;33m([0m[1;34m'../01_Dataset/dataset_28x28/X_test.npy'[0m[1;33m)[0m[1;33m.[0m[0mastype[0m[1;33m([0m[0mnp[0m[1;33m.[0m[0mfloat32[0m[1;33m)[0m [1;33m*[0m [1;36m1.0[0m[1;33m/[0m[1;36m255.0[0m  [1;31m# normalisieren[0m[1;33m[0m[1;33m[0m[0m

[1;31mNameError[0m: name 'load' is not defined
NameError: name 'load' is not defined

