Traceback (most recent call last):
  File "C:\Users\Martin\anaconda3\envs\py37\lib\site-packages\jupyter_cache\executors\utils.py", line 56, in single_nb_execution
    record_timing=False,
  File "C:\Users\Martin\anaconda3\envs\py37\lib\site-packages\nbclient\client.py", line 1112, in execute
    return NotebookClient(nb=nb, resources=resources, km=km, **kwargs).execute()
  File "C:\Users\Martin\anaconda3\envs\py37\lib\site-packages\nbclient\util.py", line 74, in wrapped
    return just_run(coro(*args, **kwargs))
  File "C:\Users\Martin\anaconda3\envs\py37\lib\site-packages\nbclient\util.py", line 53, in just_run
    return loop.run_until_complete(coro)
  File "C:\Users\Martin\anaconda3\envs\py37\lib\asyncio\base_events.py", line 587, in run_until_complete
    return future.result()
  File "C:\Users\Martin\anaconda3\envs\py37\lib\site-packages\nbclient\client.py", line 554, in async_execute
    cell, index, execution_count=self.code_cells_executed + 1
  File "C:\Users\Martin\anaconda3\envs\py37\lib\site-packages\nbclient\client.py", line 857, in async_execute_cell
    self._check_raise_for_error(cell, exec_reply)
  File "C:\Users\Martin\anaconda3\envs\py37\lib\site-packages\nbclient\client.py", line 760, in _check_raise_for_error
    raise CellExecutionError.from_cell_and_msg(cell, exec_reply_content)
nbclient.exceptions.CellExecutionError: An error occurred while executing the following cell:
------------------
import cv2

img = cv2.imread('pozi/pozi800.jpg', cv2.IMREAD_UNCHANGED)

print('Original Dimensions : ',img.shape)

scale_percent = 50 # percent of original size
width = int(img.shape[1] * scale_percent / 100)
height = int(img.shape[0] * scale_percent / 100)
dim = (width, height)

#resize image
resized = cv2.resize(img, dim, interpolation = cv2.INTER_AREA)

print('Resized Dimensions : ',resized.shape)

cv2.imshow("Resized image", resized)
cv2.waitKey(0)
cv2.destroyAllWindows()
------------------

[1;31m---------------------------------------------------------------------------[0m
[1;31mModuleNotFoundError[0m                       Traceback (most recent call last)
[1;32m~\AppData\Local\Temp/ipykernel_23276/1098803240.py[0m in [0;36m<module>[1;34m[0m
[1;32m----> 1[1;33m [1;32mimport[0m [0mcv2[0m[1;33m[0m[1;33m[0m[0m
[0m[0;32m      2[0m [1;33m[0m[0m
[0;32m      3[0m [0mimg[0m [1;33m=[0m [0mcv2[0m[1;33m.[0m[0mimread[0m[1;33m([0m[1;34m'pozi/pozi800.jpg'[0m[1;33m,[0m [0mcv2[0m[1;33m.[0m[0mIMREAD_UNCHANGED[0m[1;33m)[0m[1;33m[0m[1;33m[0m[0m
[0;32m      4[0m [1;33m[0m[0m
[0;32m      5[0m [0mprint[0m[1;33m([0m[1;34m'Original Dimensions : '[0m[1;33m,[0m[0mimg[0m[1;33m.[0m[0mshape[0m[1;33m)[0m[1;33m[0m[1;33m[0m[0m

[1;31mModuleNotFoundError[0m: No module named 'cv2'
ModuleNotFoundError: No module named 'cv2'

