Traceback (most recent call last):
  File "C:\Users\Martin\anaconda3\envs\py37\lib\site-packages\jupyter_cache\executors\utils.py", line 56, in single_nb_execution
    record_timing=False,
  File "C:\Users\Martin\anaconda3\envs\py37\lib\site-packages\nbclient\client.py", line 1112, in execute
    return NotebookClient(nb=nb, resources=resources, km=km, **kwargs).execute()
  File "C:\Users\Martin\anaconda3\envs\py37\lib\site-packages\nbclient\util.py", line 74, in wrapped
    return just_run(coro(*args, **kwargs))
  File "C:\Users\Martin\anaconda3\envs\py37\lib\site-packages\nbclient\util.py", line 53, in just_run
    return loop.run_until_complete(coro)
  File "C:\Users\Martin\anaconda3\envs\py37\lib\asyncio\base_events.py", line 587, in run_until_complete
    return future.result()
  File "C:\Users\Martin\anaconda3\envs\py37\lib\site-packages\nbclient\client.py", line 554, in async_execute
    cell, index, execution_count=self.code_cells_executed + 1
  File "C:\Users\Martin\anaconda3\envs\py37\lib\site-packages\nbclient\client.py", line 857, in async_execute_cell
    self._check_raise_for_error(cell, exec_reply)
  File "C:\Users\Martin\anaconda3\envs\py37\lib\site-packages\nbclient\client.py", line 760, in _check_raise_for_error
    raise CellExecutionError.from_cell_and_msg(cell, exec_reply_content)
nbclient.exceptions.CellExecutionError: An error occurred while executing the following cell:
------------------
from PIL import Image

im1 = Image.open(r'path where the PNG is stored\file name.png')
im1.save(r'path where the JPG will be stored\new file name.jpg')
------------------

[1;31m---------------------------------------------------------------------------[0m
[1;31mFileNotFoundError[0m                         Traceback (most recent call last)
[1;32m~\AppData\Local\Temp/ipykernel_19472/3998500180.py[0m in [0;36m<module>[1;34m[0m
[0;32m      1[0m [1;32mfrom[0m [0mPIL[0m [1;32mimport[0m [0mImage[0m[1;33m[0m[1;33m[0m[0m
[0;32m      2[0m [1;33m[0m[0m
[1;32m----> 3[1;33m [0mim1[0m [1;33m=[0m [0mImage[0m[1;33m.[0m[0mopen[0m[1;33m([0m[1;34mr'path where the PNG is stored\file name.png'[0m[1;33m)[0m[1;33m[0m[1;33m[0m[0m
[0m[0;32m      4[0m [0mim1[0m[1;33m.[0m[0msave[0m[1;33m([0m[1;34mr'path where the JPG will be stored\new file name.jpg'[0m[1;33m)[0m[1;33m[0m[1;33m[0m[0m

[1;32m~\anaconda3\envs\py37\lib\site-packages\PIL\Image.py[0m in [0;36mopen[1;34m(fp, mode, formats)[0m
[0;32m   2973[0m [1;33m[0m[0m
[0;32m   2974[0m     [1;32mif[0m [0mfilename[0m[1;33m:[0m[1;33m[0m[1;33m[0m[0m
[1;32m-> 2975[1;33m         [0mfp[0m [1;33m=[0m [0mbuiltins[0m[1;33m.[0m[0mopen[0m[1;33m([0m[0mfilename[0m[1;33m,[0m [1;34m"rb"[0m[1;33m)[0m[1;33m[0m[1;33m[0m[0m
[0m[0;32m   2976[0m         [0mexclusive_fp[0m [1;33m=[0m [1;32mTrue[0m[1;33m[0m[1;33m[0m[0m
[0;32m   2977[0m [1;33m[0m[0m

[1;31mFileNotFoundError[0m: [Errno 2] No such file or directory: 'path where the PNG is stored\\file name.png'
FileNotFoundError: [Errno 2] No such file or directory: 'path where the PNG is stored\\file name.png'

